<?xml version="1.0" ?>
<!-- =================================================================================== -->
<!-- |    This document was autogenerated by xacro from orne_box.urdf.xacro            | -->
<!-- |    EDITING THIS FILE BY HAND IS NOT RECOMMENDED                                 | -->
<!-- =================================================================================== -->
<robot name="orne_box" xmlns:controller="http://playerstage.sourceforge.net/gazebo/xmlschema/#controller" xmlns:interface="http://playerstage.sourceforge.net/gazebo/xmlschema/#interface">
  <material name="black">
    <color rgba="0.0 0.0 0.0 1.0"/>
  </material>
  <material name="brown">
    <color rgba="0.8705882352941177 0.8117647058823529 0.7647058823529411 1.0"/>
  </material>
  <material name="red">
    <color rgba="0.8 0.0 0.0 1.0"/>
  </material>
  <material name="orange">
    <color rgba="1.0 0.4235294117647059 0.0392156862745098 1.0"/>
  </material>
  <material name="yellow">
    <color rgba="0.8 0.8 0.0 1.0"/>
  </material>
  <material name="green">
    <color rgba="0.0 0.8 0.0 1.0"/>
  </material>
  <material name="cyan">
    <color rgba="0.0 0.8 0.8 1.0"/>
  </material>
  <material name="bule">
    <color rgba="0.0 0.0 0.8 1.0"/>
  </material>
  <material name="purple">
    <color rgba="0.8 0.0 0.8 1.0"/>
  </material>
  <material name="gray">
    <color rgba="0.5 0.5 0.5 1.0"/>
  </material>
  <material name="white">
    <color rgba="1.0 1.0 1.0 1.0"/>
  </material>
  <gazebo reference="left_caster_wheel_link">
    <mu1>0.75</mu1>
    <mu2>0.75</mu2>
    <kp>1000000.0</kp>
    <kd>100.0</kd>
    <minDepth>0.001</minDepth>
    <maxVel>1.0</maxVel>
  </gazebo>
  <gazebo reference="right_caster_wheel_link">
    <mu1>0.75</mu1>
    <mu2>0.75</mu2>
    <kp>1000000.0</kp>
    <kd>100.0</kd>
    <minDepth>0.001</minDepth>
    <maxVel>1.0</maxVel>
  </gazebo>
  <gazebo reference="left_wheel">
    <mu1>0.85</mu1>
    <mu2>0.85</mu2>
    <kp>1000000.0</kp>
    <kd>100.0</kd>
    <minDepth>0.001</minDepth>
    <maxVel>1.0</maxVel>
    <material>Gazebo/White</material>
  </gazebo>
  <gazebo reference="right_wheel">
    <mu1>0.85</mu1>
    <mu2>0.85</mu2>
    <kp>1000000.0</kp>
    <kd>100.0</kd>
    <minDepth>0.001</minDepth>
    <maxVel>1.0</maxVel>
    <material>Gazebo/White</material>
  </gazebo>
  <!-- @TODO More clear boolean operation -->
  <!-- <gazebo>
      <plugin name="gazebo_ros_control" filename="libgazebo_ros_control.so">
        <robotNamespace>orne_box</robotNamespace>
        <robotSimType>gazebo_ros_control/DefaultRobotHWSim</robotSimType>
      </plugin>
    </gazebo> -->
  <gazebo>
    <plugin filename="libgazebo_ros_diff_drive.so" name="gazebo_ros_control">
      <always_on>true</always_on>
      <robotNamespace>/orne_box</robotNamespace>
      <!-- frame and cmd_vel -->
      <command_topic>cmd_vel</command_topic>
      <odometry_topic>odom</odometry_topic>
      <odometry_frame>odom</odometry_frame>
      <!-- <odometrySource>world</odometrySource> -->
      <robot_base_frame>base_footprint</robot_base_frame>
      <update_rate>30</update_rate>
      <!-- wheels -->
      <left_joint>left_wheel_joint</left_joint>
      <right_joint>right_wheel_joint</right_joint>
      <!-- kinematics -->
      <wheel_separation>0.46</wheel_separation>
      <wheel_diameter>0.304</wheel_diameter>
      <wheel_acceleration>1</wheel_acceleration>
      <max_wheel_torque>20</max_wheel_torque>
      <max_wheel_acceleration>1.0</max_wheel_acceleration>
      <!-- output -->
      <publish_odom>true</publish_odom>
      <publish_odom_tf>true</publish_odom_tf>
      <publish_wheel_tf>false</publish_wheel_tf>
    </plugin>
  </gazebo>
  <gazebo reference="base_link">
    <material>Gazebo/Orange</material>
  </gazebo>
  <!-- imu -->
  <!-- <gazebo reference="imu_link">
      <sensor type="imu" name="imu">
        <plugin filename="libgazebo_ros_imu_sensor.so" name="imu_plugin">
          <ros>
            <remapping>~/out:=imu</remapping>
          </ros>
          <initial_orientation_as_reference>false</initial_orientation_as_reference>
        </plugin>
        <always_on>true</always_on>
        <update_rate>100</update_rate>
        <visualize>true</visualize>

        <imu>
        <angular_velocity>
          <x>
            <noise type="gaussian">
                <mean>0.0</mean>
                <stddev>2e-4</stddev>
                <bias_mean>0.0000075</bias_mean>
                <bias_stddev>0.0000008</bias_stddev>
              </noise>
            </x>
            <y>
              <noise type="gaussian">
                <mean>0.0</mean>
                <stddev>2e-4</stddev>
                <bias_mean>0.0000075</bias_mean>
                <bias_stddev>0.0000008</bias_stddev>
              </noise>
            </y>
            <z>
              <noise type="gaussian">
                <mean>0.0</mean>
                <stddev>2e-4</stddev>
                <bias_mean>0.0000075</bias_mean>
                <bias_stddev>0.0000008</bias_stddev>
              </noise>
            </z>
          </angular_velocity>
          <linear_acceleration>
            <x>
              <noise type="gaussian">
                <mean>0.0</mean>
                <stddev>1.7e-2</stddev>
                <bias_mean>0.1</bias_mean>
                <bias_stddev>0.001</bias_stddev>
              </noise>
            </x>
            <y>
              <noise type="gaussian">
                <mean>0.0</mean>
                <stddev>1.7e-2</stddev>
                <bias_mean>0.1</bias_mean>
                <bias_stddev>0.001</bias_stddev>
              </noise>
            </y>
            <z>
              <noise type="gaussian">
                <mean>0.0</mean>
                <stddev>1.7e-2</stddev>
                <bias_mean>0.1</bias_mean>
                <bias_stddev>0.001</bias_stddev>
              </noise>
            </z>
          </linear_acceleration>
        </imu>
      </sensor>
      <material>Gazebo/Green</material>
    
    </gazebo> -->
  <!-- hokuyo -->
  <gazebo reference="hokuyo_link">
    <sensor name="head_hokuyo_sensor" type="ray">
      <pose>0 0 0 0 0 0</pose>
      <visualize>true</visualize>
      <update_rate>40</update_rate>
      <ray>
        <scan>
          <horizontal>
            <samples>880</samples>
            <resolution>0.25</resolution>
            <min_angle>-1.9198621771937625</min_angle>
            <max_angle>1.9198621771937625</max_angle>
          </horizontal>
          <vertical>
            <samples>1</samples>
            <resolution>1</resolution>
          </vertical>
        </scan>
        <range>
          <min>0.10</min>
          <max>30.0</max>
          <resolution>0.01</resolution>
        </range>
        <noise>
          <type>gaussian</type>
          <!-- Noise parameters based on published spec for Hokuyo laser
                 achieving "+-30mm" accuracy at range < 10m.  A mean of 0.0m and
                 stddev of 0.01m will put 99.7% of samples within 0.03m of the true
                 reading. -->
          <mean>0.0</mean>
          <stddev>0.01</stddev>
        </noise>
      </ray>
      <plugin filename="libgazebo_ros_ray_sensor.so" name="gazebo_ros_head_hokuyo_controller">
        <ros>
          <remapping>~/out:=scan</remapping>
        </ros>
        <frame_name>hokuyo_link</frame_name>
        <output_type>sensor_msgs/LaserScan</output_type>
      </plugin>
    </sensor>
    <material>Gazebo/Black</material>
  </gazebo>
  <!-- base_footprint-->
  <link name="base_footprint"/>
  <joint name="base_joint" type="fixed">
    <origin xyz="0.0 0.0 0.0"/>
    <parent link="base_footprint"/>
    <child link="base_link"/>
  </joint>
  <!-- base_link -->
  <link name="base_link">
    <visual>
      <origin rpy="0 0 0" xyz="0.090 0 0.1715"/>
      <geometry>
        <box size="0.400 0.404 0.202"/>
      </geometry>
      <material name="orange"/>
    </visual>
    <visual>
      <origin rpy="0 0 0" xyz="0.36125 0 0.2625"/>
      <geometry>
        <box size="0.1425 0.404 0.020"/>
      </geometry>
      <material name="orange"/>
    </visual>
    <visual>
      <origin rpy="0 0 0" xyz="0.35625 0 0.156"/>
      <geometry>
        <box size="0.1325 0.404 0.020"/>
      </geometry>
      <material name="orange"/>
    </visual>
    <visual>
      <origin rpy="0 0 0" xyz="-0.120 0 0.4815"/>
      <geometry>
        <box size="0.020 0.404 0.822"/>
      </geometry>
      <material name="orange"/>
    </visual>
    <collision>
      <origin rpy="0 0 0" xyz="0.090 0 0.1715"/>
      <geometry>
        <box size="0.400 0.404 0.202"/>
      </geometry>
    </collision>
    <collision>
      <origin rpy="0 0 0" xyz="0.36125 0 0.2625"/>
      <geometry>
        <box size="0.1425 0.404 0.020"/>
      </geometry>
    </collision>
    <collision>
      <origin rpy="0 0 0" xyz="0.35625 0 0.156"/>
      <geometry>
        <box size="0.1325 0.404 0.020"/>
      </geometry>
    </collision>
    <collision>
      <origin rpy="0 0 0" xyz="-0.120 0 0.4815"/>
      <geometry>
        <box size="0.020 0.404 0.822"/>
      </geometry>
    </collision>
    <inertial>
      <origin rpy="0 0 0" xyz="0.090 0 0.1715"/>
      <mass value="25.0"/>
      <inertia ixx="1.12" ixy="0.0" ixz="0.0" iyy="3.46" iyz="0.0" izz="3.9"/>
    </inertial>
  </link>
  <link name="left_caster_wheel_link">
    <visual>
      <origin rpy="0 0 0" xyz="0 0 0"/>
      <geometry>
        <cylinder length="0.025" radius="0.050"/>
      </geometry>
      <material name="purple"/>
    </visual>
    <collision>
      <origin rpy="0 0 0" xyz="0 0 0"/>
      <geometry>
        <cylinder length="0.025" radius="0.050"/>
      </geometry>
    </collision>
    <inertial>
      <origin xyz="0 0 0"/>
      <mass value="0.2"/>
      <inertia ixx="0.001" ixy="0.0" ixz="0.0" iyy="0.001" iyz="0.0" izz="0.001"/>
    </inertial>
  </link>
  <link name="left_caster_swivel_link">
    <visual>
      <origin rpy="0 0 0" xyz="0 0 0"/>
      <geometry>
        <box size="0.05 0.05 0.01"/>
      </geometry>
      <material name="purple"/>
    </visual>
    <collision>
      <origin rpy="0 0 0" xyz="0 0 0"/>
      <geometry>
        <box size="0.05 0.05 0.01"/>
      </geometry>
    </collision>
    <inertial>
      <origin xyz="0 0 0"/>
      <mass value="0.1"/>
      <inertia ixx="0.001" ixy="0.0" ixz="0.0" iyy="0.001" iyz="0.0" izz="0.001"/>
    </inertial>
  </link>
  <joint name="left_caster_wheel_joint" type="continuous">
    <parent link="left_caster_swivel_link"/>
    <child link="left_caster_wheel_link"/>
    <origin rpy="-1.5707963267948966 0 0" xyz="0.03 0.0 -0.065"/>
    <axis xyz="0 0 1"/>
    <limit effort="0.0" lower="-1e15" upper="1e15" velocity="0.0"/>
    <dynamics damping="0.01"/>
  </joint>
  <joint name="left_caster_swivel_joint" type="continuous">
    <parent link="base_link"/>
    <child link="left_caster_swivel_link"/>
    <origin rpy="0 0 0" xyz="0.362 0.150 0.115"/>
    <axis xyz="0 0 1"/>
    <limit effort="0.0" lower="-1e15" upper="1e15" velocity="0.0"/>
    <dynamics damping="0.01"/>
  </joint>
  <link name="right_caster_wheel_link">
    <visual>
      <origin rpy="0 0 0" xyz="0 0 0"/>
      <geometry>
        <cylinder length="0.025" radius="0.050"/>
      </geometry>
      <material name="purple"/>
    </visual>
    <collision>
      <origin rpy="0 0 0" xyz="0 0 0"/>
      <geometry>
        <cylinder length="0.025" radius="0.050"/>
      </geometry>
    </collision>
    <inertial>
      <origin xyz="0 0 0"/>
      <mass value="0.2"/>
      <inertia ixx="0.001" ixy="0.0" ixz="0.0" iyy="0.001" iyz="0.0" izz="0.001"/>
    </inertial>
  </link>
  <link name="right_caster_swivel_link">
    <visual>
      <origin rpy="0 0 0" xyz="0 0 0"/>
      <geometry>
        <box size="0.05 0.05 0.01"/>
      </geometry>
      <material name="purple"/>
    </visual>
    <collision>
      <origin rpy="0 0 0" xyz="0 0 0"/>
      <geometry>
        <box size="0.05 0.05 0.01"/>
      </geometry>
    </collision>
    <inertial>
      <origin xyz="0 0 0"/>
      <mass value="0.1"/>
      <inertia ixx="0.001" ixy="0.0" ixz="0.0" iyy="0.001" iyz="0.0" izz="0.001"/>
    </inertial>
  </link>
  <joint name="right_caster_wheel_joint" type="continuous">
    <parent link="right_caster_swivel_link"/>
    <child link="right_caster_wheel_link"/>
    <origin rpy="-1.5707963267948966 0 0" xyz="0.03 0.0 -0.065"/>
    <axis xyz="0 0 1"/>
    <limit effort="0.0" lower="-1e15" upper="1e15" velocity="0.0"/>
    <dynamics damping="0.01"/>
  </joint>
  <joint name="right_caster_swivel_joint" type="continuous">
    <parent link="base_link"/>
    <child link="right_caster_swivel_link"/>
    <origin rpy="0 0 0" xyz="0.362 -0.150 0.115"/>
    <axis xyz="0 0 1"/>
    <limit effort="0.0" lower="-1e15" upper="1e15" velocity="0.0"/>
    <dynamics damping="0.01"/>
  </joint>
  <joint name="left_wheel_joint" type="continuous">
    <parent link="base_link"/>
    <child link="wheel_left_link"/>
    <origin rpy="-1.5707963267948966 0 0" xyz="0.0 0.23075 0.152"/>
    <axis xyz="0 0 1"/>
    <limit effort="10.5" lower="-1e15" upper="1e15" velocity="10.0"/>
    <dynamics damping="0.05"/>
  </joint>
  <transmission name="transmission_left">
    <type>transmission_interface/SimpleTransmission</type>
    <joint name="left_wheel_joint">
      <hardwareInterface>hardware_interface/VelocityJointInterface</hardwareInterface>
    </joint>
    <actuator name="left_motor">
      <hardwareInterface>hardware_interface/VelocityJointInterface</hardwareInterface>
      <mechanicalReduction>1</mechanicalReduction>
    </actuator>
  </transmission>
  <link name="wheel_left_link">
    <visual>
      <origin rpy="0 0 0" xyz="0.0 0.0 0.0"/>
      <geometry>
        <cylinder length="0.045" radius="0.152"/>
      </geometry>
      <material name="white"/>
    </visual>
    <collision>
      <origin rpy="0 0 0" xyz="0.0 0.0 0.0"/>
      <geometry>
        <cylinder length="0.045" radius="0.152"/>
      </geometry>
    </collision>
    <inertial>
      <origin xyz="0 0 0"/>
      <mass value="0.15"/>
      <inertia ixx="0.005" ixy="0.0" ixz="0.0" iyy="0.005" iyz="0.0" izz="0.01"/>
    </inertial>
  </link>
  <joint name="right_wheel_joint" type="continuous">
    <parent link="base_link"/>
    <child link="wheel_right_link"/>
    <origin rpy="-1.5707963267948966 0 0" xyz="0.0 -0.23075 0.152"/>
    <axis xyz="0 0 1"/>
    <limit effort="10.5" lower="-1e15" upper="1e15" velocity="10.0"/>
    <dynamics damping="0.05"/>
  </joint>
  <transmission name="transmission_right">
    <type>transmission_interface/SimpleTransmission</type>
    <joint name="right_wheel_joint">
      <hardwareInterface>hardware_interface/VelocityJointInterface</hardwareInterface>
    </joint>
    <actuator name="right_motor">
      <hardwareInterface>hardware_interface/VelocityJointInterface</hardwareInterface>
      <mechanicalReduction>1</mechanicalReduction>
    </actuator>
  </transmission>
  <link name="wheel_right_link">
    <visual>
      <origin rpy="0 0 0" xyz="0.0 0.0 0.0"/>
      <geometry>
        <cylinder length="0.045" radius="0.140"/>
      </geometry>
      <material name="white"/>
    </visual>
    <collision>
      <origin rpy="0 0 0" xyz="0.0 0.0 0.0"/>
      <geometry>
        <cylinder length="0.045" radius="0.140"/>
      </geometry>
    </collision>
    <inertial>
      <origin xyz="0 0 0"/>
      <mass value="0.15"/>
      <inertia ixx="0.005" ixy="0.0" ixz="0.0" iyy="0.005" iyz="0.0" izz="0.01"/>
    </inertial>
  </link>
  <!-- Setting for IMU -->
  <!-- <xacro:sensor_imu name="imu" parent="base_link" size="0.05 0.05 0.05">
    <origin xyz="0.23 0.0 0.270" rpy="${-PI} 0 ${PI/2}"/>
  </xacro:sensor_imu> -->
  <!-- <xacro:sensor_imu name="imu" parent="base_link" size="0.05 0.05 0.05">
    <origin xyz="0.23 0.0 0.270" rpy="0 0 0"/>
    <origin_child xyz="0.0 0.0 0.0" rpy="0 0 0"/>

  </xacro:sensor_imu> -->
  <joint name="hokuyo_joint" type="fixed">
    <axis xyz="1 0 0"/>
    <origin rpy="0 0 0" xyz="0.374295 0 0.2185"/>
    <parent link="base_link"/>
    <child link="hokuyo_link"/>
  </joint>
  <link name="hokuyo_link">
    <inertial>
      <origin rpy="0.0 0.0 0.0" xyz="0.0 0.0 0.0"/>
      <mass value="0.2"/>
      <inertia ixx="0.005" ixy="0.0" ixz="0.0" iyy="0.005" iyz="0.0" izz="0.005"/>
    </inertial>
    <visual>
      <origin rpy="0 0 0" xyz="0 0 0"/>
      <geometry>
        <box size="0.05 0.05 0.05"/>
      </geometry>
      <material name="black"/>
    </visual>
  </link>
  <!-- <xacro:sensor_hokuyo name="mirror_lidar" parent="base_link" size="0.05 0.05 0.05"> -->
  <!-- <origin xyz="0.43 0.0 0.34" rpy="0 0.314 0"/> -->
  <!-- </xacro:sensor_hokuyo> -->
</robot>
